Traceback (most recent call last):
  File "/mnt/d/雷电大魔王/LoRA_Jittor/LoRA_pytorch_NLG/src/gpt2_decode.py", line 14, in <module>
  File "/home/dmw/anaconda3/envs/lora/lib/python3.9/site-packages/torch/__init__.py", line 1146, in <module>
    _C._initExtension(manager_path())
  File "/home/dmw/anaconda3/envs/lora/lib/python3.9/site-packages/torch/cuda/__init__.py", line 197, in <module>
    _lazy_call(_check_capability)
  File "/home/dmw/anaconda3/envs/lora/lib/python3.9/site-packages/torch/cuda/__init__.py", line 195, in _lazy_call
    _queued_calls.append((callable, traceback.format_stack()))
  File "/home/dmw/anaconda3/envs/lora/lib/python3.9/traceback.py", line 197, in format_stack
    return format_list(extract_stack(f, limit=limit))
  File "/home/dmw/anaconda3/envs/lora/lib/python3.9/traceback.py", line 211, in extract_stack
    stack = StackSummary.extract(walk_stack(f), limit=limit)
  File "/home/dmw/anaconda3/envs/lora/lib/python3.9/traceback.py", line 366, in extract
    f.line
  File "/home/dmw/anaconda3/envs/lora/lib/python3.9/traceback.py", line 288, in line
    self._line = linecache.getline(self.filename, self.lineno).strip()
  File "/home/dmw/anaconda3/envs/lora/lib/python3.9/linecache.py", line 30, in getline
    lines = getlines(filename, module_globals)
  File "/home/dmw/anaconda3/envs/lora/lib/python3.9/linecache.py", line 46, in getlines
    return updatecache(filename, module_globals)
  File "/home/dmw/anaconda3/envs/lora/lib/python3.9/linecache.py", line 137, in updatecache
    lines = fp.readlines()
  File "/home/dmw/anaconda3/envs/lora/lib/python3.9/codecs.py", line 322, in decode
    (result, consumed) = self._buffer_decode(data, self.errors, final)
UnicodeDecodeError: 'utf-8' codec can't decode byte 0xd0 in position 3433: invalid continuation byte
